Workbook

Sheet MINHA CARTEIRA
A1: AÇÃO | B1: COD AÇÃO | C1: VAR. | D1: VALOR | E1: COMPRA | F1: RENT | G1: Nº AÇÕES | H1: VAL. INVEST. | I1: VAL. ATUAL | J1: LUCRO/PERDA
A2: #VALUE! | B2: BBSE3 | C2: {=_FV(A2,"Variação (%)",TRUE)} -> 0.008 | D2: {=_FV(A2,"Preço")} -> 34.02 | E2: 36.38 | F2: =(D2-E2)/E2 -> -0.064870808 | G2: 300 | H2: =Tabela4[[#This Row],[Nº AÇÕES ]]*Tabela4[[#This Row],[COMPRA]] -> 10914 | I2: =Tabela4[[#This Row],[Nº AÇÕES ]]*Tabela4[[#This Row],[VALOR ]] -> 10206 | J2: =Tabela4[[#This Row],[VAL. ATUAL]]-Tabela4[[#This Row],[VAL. INVEST.]] -> -708
A3: #VALUE! | B3: VALE3 | C3: {=_FV(A3,"Variação (%)",TRUE)} -> 0.025554 | D3: {=_FV(A3,"Preço")} -> 81.47 | E3: 79.53 | F3: =(D3-E3)/E3 -> 0.024393311 | G3: 300 | H3: =Tabela4[[#This Row],[Nº AÇÕES ]]*Tabela4[[#This Row],[COMPRA]] -> 23859 | I3: =Tabela4[[#This Row],[Nº AÇÕES ]]*Tabela4[[#This Row],[VALOR ]] -> 24441 | J3: =Tabela4[[#This Row],[VAL. ATUAL]]-Tabela4[[#This Row],[VAL. INVEST.]] -> 582
A4: #VALUE! | B4: PETR4 | C4: {=_FV(A4,"Variação (%)",TRUE)} -> 0.000817 | D4: {=_FV(A4,"Preço")} -> 49 | E4: 46.36 | F4: =(D4-E4)/E4 -> 0.056945643 | G4: 500 | H4: =Tabela4[[#This Row],[Nº AÇÕES ]]*Tabela4[[#This Row],[COMPRA]] -> 23180 | I4: =Tabela4[[#This Row],[Nº AÇÕES ]]*Tabela4[[#This Row],[VALOR ]] -> 24500 | J4: =Tabela4[[#This Row],[VAL. ATUAL]]-Tabela4[[#This Row],[VAL. INVEST.]] -> 1320
A5: #VALUE! | B5: ABEV3 | C5: {=_FV(A5,"Variação (%)",TRUE)} -> 0.018144 | D5: {=_FV(A5,"Preço")} -> 14.59 | E5: 13.22 | F5: =(D5-E5)/E5 -> 0.10363086 | G5: 900 | H5: =Tabela4[[#This Row],[Nº AÇÕES ]]*Tabela4[[#This Row],[COMPRA]] -> 11898 | I5: =Tabela4[[#This Row],[Nº AÇÕES ]]*Tabela4[[#This Row],[VALOR ]] -> 13131 | J5: =Tabela4[[#This Row],[VAL. ATUAL]]-Tabela4[[#This Row],[VAL. INVEST.]] -> 1233
A6: =SUBTOTAL(103,Tabela4[AÇÃO]) -> 4 | B6: 4 | F6: =SUM(Tabela4[RENT]) -> 0.12009901 | H6: =SUBTOTAL(109,Tabela4[VAL. INVEST.]) -> 69851 | I6: =SUBTOTAL(109,Tabela4[VAL. ATUAL]) -> 72278 | J6: =SUM(Tabela4[LUCRO/PERDA]) -> 2427

Sheet CARTEIRA RENATO
A1: DATA | B1: COD AÇÃO | C1: Variação | D1: Preço | E1: VAL. REAIS (R$) | F1: COMPRA | G1: RENT | H1: Nº AÇÕES | I1: VAL. INVEST. | J1: VAL. ATUAL | K1: LUCRO/PERDA
A2: 46125 | B2: #VALUE! | C2: {=_FV(Tabela5[[#This Row],[COD AÇÃO]],"Variação")} -> 0.04 | D2: {=_FV(Tabela5[[#This Row],[COD AÇÃO]],"Preço")} -> 49 | E2: =Tabela5[[#This Row],[Preço]] -> 49 | F2: 49.68 | G2: =(D2-F2)/F2 -> -0.013687601 | H2: 10 | I2: =Tabela5[[#This Row],[Nº AÇÕES ]]*Tabela5[[#This Row],[COMPRA]] -> 496.8 | J2: =Tabela5[[#This Row],[Nº AÇÕES ]]*Tabela5[[#This Row],[Preço]] -> 490 | K2: =Tabela5[[#This Row],[VAL. ATUAL]]-Tabela5[[#This Row],[VAL. INVEST.]] -> -6.8
A3: 46125 | B3: #VALUE! | C3: {=_FV(Tabela5[[#This Row],[COD AÇÃO]],"Variação")} -> 2.03 | D3: {=_FV(Tabela5[[#This Row],[COD AÇÃO]],"Preço")} -> 81.47 | E3: =Tabela5[[#This Row],[Preço]] -> 81.47 | F3: 87.68 | G3: =(D3-F3)/F3 -> -0.07082573 | H3: 10 | I3: =Tabela5[[#This Row],[Nº AÇÕES ]]*Tabela5[[#This Row],[COMPRA]] -> 876.8 | J3: =Tabela5[[#This Row],[Nº AÇÕES ]]*Tabela5[[#This Row],[Preço]] -> 814.7 | K3: =Tabela5[[#This Row],[VAL. ATUAL]]-Tabela5[[#This Row],[VAL. INVEST.]] -> -62.1
A4: 46125 | B4: #VALUE! | C4: {=_FV(Tabela5[[#This Row],[COD AÇÃO]],"Variação")} -> 0.53 | D4: {=_FV(Tabela5[[#This Row],[COD AÇÃO]],"Preço")} -> 22.24 | E4: =Tabela5[[#This Row],[Preço]] -> 22.24 | F4: 24.6 | G4: =(D4-F4)/F4 -> -0.095934959 | H4: 26 | I4: =Tabela5[[#This Row],[Nº AÇÕES ]]*Tabela5[[#This Row],[COMPRA]] -> 639.6 | J4: =Tabela5[[#This Row],[Nº AÇÕES ]]*Tabela5[[#This Row],[Preço]] -> 578.24 | K4: =Tabela5[[#This Row],[VAL. ATUAL]]-Tabela5[[#This Row],[VAL. INVEST.]] -> -61.36
A5: 46125 | B5: #VALUE! | C5: {=_FV(Tabela5[[#This Row],[COD AÇÃO]],"Variação")} -> 0.26 | D5: {=_FV(Tabela5[[#This Row],[COD AÇÃO]],"Preço")} -> 14.59 | E5: =Tabela5[[#This Row],[Preço]] -> 14.59 | F5: 15.86 | G5: =(D5-F5)/F5 -> -0.080075662 | H5: 19 | I5: =Tabela5[[#This Row],[Nº AÇÕES ]]*Tabela5[[#This Row],[COMPRA]] -> 301.34 | J5: =Tabela5[[#This Row],[Nº AÇÕES ]]*Tabela5[[#This Row],[Preço]] -> 277.21 | K5: =Tabela5[[#This Row],[VAL. ATUAL]]-Tabela5[[#This Row],[VAL. INVEST.]] -> -24.13
A6: 46125 | B6: #VALUE! | C6: {=_FV(Tabela5[[#This Row],[COD AÇÃO]],"Variação")} -> 0.04 | D6: {=_FV(Tabela5[[#This Row],[COD AÇÃO]],"Preço")} -> 7.94 | E6: =Tabela5[[#This Row],[Preço]] -> 7.94 | F6: 8.12 | G6: =(D6-F6)/F6 -> -0.022167488 | H6: 44 | I6: =Tabela5[[#This Row],[Nº AÇÕES ]]*Tabela5[[#This Row],[COMPRA]] -> 357.28 | J6: =Tabela5[[#This Row],[Nº AÇÕES ]]*Tabela5[[#This Row],[Preço]] -> 349.36 | K6: =Tabela5[[#This Row],[VAL. ATUAL]]-Tabela5[[#This Row],[VAL. INVEST.]] -> -7.92
B7: =SUBTOTAL(103,Tabela5[COD AÇÃO]) -> 5 | G7: =SUBTOTAL(109,Tabela5[RENT]) -> -0.28269144 | I7: =SUBTOTAL(109,Tabela5[VAL. INVEST.]) -> 2671.82 | J7: =SUBTOTAL(109,Tabela5[VAL. ATUAL]) -> 2509.51 | K7: =SUM(Tabela5[LUCRO/PERDA]) -> -162.31
A13: DATA | B13: COD AÇÃO | C13: Variação | D13: Preço | E13: VAL. REAIS (R$) | F13: COMPRA | G13: RENT | H13: Nº AÇÕES | I13: VAL. INVEST. | J13: VAL. ATUAL | K13: LUCRO/PERDA
A14: 46125 | B14: #VALUE! | C14: {=_FV(B14,"Variação")} -> 1.0355 | D14: {=_FV(B14,"Preço")} -> 64.055 | E14: =D14*CAMBIO!$C$2 -> 317.32847 | F14: 63.73 | G14: =(D14-F14)/F14 -> 0.0050996391 | H14: 20.22817 | I14: 1293.39 | J14: =H14*D14 -> 1295.7154 | K14: =J14-I14 -> 2.3254293
B15: =SUBTOTAL(103,Tabela6[COD AÇÃO]) -> 1 | G15: =SUBTOTAL(109,Tabela6[RENT]) -> 0.0050996391 | K15: =SUM(Tabela6[LUCRO/PERDA]) -> 2.3254293
A19: DATA | B19: COD AÇÃO | C19: Variação | D19: Preço | E19: VAL. REAIS (R$) | F19: COMPRA | G19: RENT | H19: Nº AÇÕES | I19: VAL. INVEST. | J19: VAL. ATUAL | K19: LUCRO/PERDA
A20: 46131 | B20: #VALUE! | C20: {=_FV(B20,"Variação")} -> 2.5 | D20: {=_FV(B20,"Preço")} -> 396.33 | E20: =D20*CAMBIO!$C$2 -> 1963.4188 | F20: 375.1 | G20: =IFERROR((D20-F20)/F20,"") -> 0.05659824 | H20: 1 | I20: =H20*F20 -> 375.1 | J20: =IFERROR(H20*D20,"") -> 396.33 | K20: =IFERROR(J20-I20,"") -> 21.23
A21: 46131 | B21: #VALUE! | C21: {=_FV(B21,"Variação")} -> 2.03 | D21: {=_FV(B21,"Preço")} -> 132.46 | E21: =D21*CAMBIO!$C$2 -> 656.20684 | F21: 133.28 | G21: =IFERROR((D21-F21)/F21,"") -> -0.006152461 | H21: 1 | I21: =H21*F21 -> 133.28 | J21: =IFERROR(H21*D21,"") -> 132.46 | K21: =IFERROR(J21-I21,"") -> -0.82
A22: 46131 | B22: #VALUE! | C22: {=_FV(B22,"Variação")} -> 0.47 | D22: {=_FV(B22,"Preço")} -> 60.74 | E22: =D22*CAMBIO!$C$2 -> 300.90596 | F22: 63.61 | G22: =IFERROR((D22-F22)/F22,"") -> -0.045118692 | H22: 1 | I22: =H22*F22 -> 63.61 | J22: =IFERROR(H22*D22,"") -> 60.74 | K22: =IFERROR(J22-I22,"") -> -2.87
A23: 46131 | B23: #VALUE! | C23: {=_FV(B23,"Variação")} -> 3.09 | D23: {=_FV(B23,"Preço")} -> 100.76 | E23: =D23*CAMBIO!$C$2 -> 499.16504 | F23: 101.97 | G23: =IFERROR((D23-F23)/F23,"") -> -0.011866235 | H23: 1 | I23: =H23*F23 -> 101.97 | J23: =IFERROR(H23*D23,"") -> 100.76 | K23: =IFERROR(J23-I23,"") -> -1.21
A24: 46131 | B24: #VALUE! | C24: {=_FV(B24,"Variação")} -> 0.375 | D24: {=_FV(B24,"Preço")} -> 20.155 | E24: =D24*CAMBIO!$C$2 -> 99.84787 | F24: 21.28 | G24: =IFERROR((D24-F24)/F24,"") -> -0.052866541 | H24: 1 | I24: =H24*F24 -> 21.28 | J24: =IFERROR(H24*D24,"") -> 20.155 | K24: =IFERROR(J24-I24,"") -> -1.125
A25: 46132 | B25: #VALUE! | C25: {=_FV(B25,"Variação")} -> 74.79 | D25: {=_FV(B25,"Preço")} -> 140 | E25: =D25*CAMBIO!$C$2 -> 693.56 | F25: 140 | G25: =IFERROR((D25-F25)/F25,"") -> 0 | H25: 1 | I25: =H25*F25 -> 140 | J25: =IFERROR(H25*D25,"") -> 140 | K25: =IFERROR(J25-I25,"") -> 0
A26: 46132 | B26: #VALUE! | C26: {=_FV(B26,"Variação")} -> 0.0001 | D26: {=_FV(B26,"Preço")} -> 1.1385 | E26: =D26*CAMBIO!$C$2 -> 5.640129 | F26: 1.1371 | G26: =IFERROR((D26-F26)/F26,"") -> 0.0012312022 | H26: 1 | I26: =H26*F26 -> 1.1371 | J26: =IFERROR(H26*D26,"") -> 1.1385 | K26: =IFERROR(J26-I26,"") -> 0.0014
B27: =SUBTOTAL(103,B20:B26) -> 7 | D27: =SUM(D20:D26) -> 851.5835 | E27: =SUM(E20:E26) -> 4218.7447 | G27: =IFERROR(SUBTOTAL(109,G20:G26),"") -> -0.058174487 | I27: =SUM(I20:I26) -> 836.3771 | J27: =SUM(J20:J26) -> 851.5835 | K27: =IFERROR(SUM(K20:K26),"") -> 15.2064
A30: DATA | B30: COD AÇÃO SMALL CAPS BR | C30: Variação | D30: Preço | E30: VAL. REAIS (R$) | F30: COMPRA | G30: RENT | H30: Nº AÇÕES | I30: VAL. INVEST. | J30: VAL. ATUAL | K30: LUCRO/PERDA
A31: 46132 | B31: #VALUE! | C31: {=_FV(B31,"Variação")} -> 0.48 | D31: {=_FV(B31,"Preço")} -> 21.63 | E31: =D31 -> 21.63 | F31: 21.9 | G31: =IFERROR((D31-F31)/F31,"") -> -0.012328767 | H31: 20 | I31: =H31*F31 -> 438 | J31: =IFERROR(H31*D31,"") -> 432.6 | K31: =IFERROR(J31-I31,"") -> -5.4
A32: 46132 | B32: #VALUE! | C32: {=_FV(B32,"Variação")} -> 0.8 | D32: {=_FV(B32,"Preço")} -> 25.75 | E32: =D32 -> 25.75 | F32: 27.28 | G32: =IFERROR((D32-F32)/F32,"") -> -0.056085044 | H32: 0 | I32: =H32*F32 -> 0 | J32: =IFERROR(H32*D32,"") -> 0 | K32: =IFERROR(J32-I32,"") -> 0
A33: 46132 | B33: #VALUE! | C33: {=_FV(B33,"Variação")} -> 0.32 | D33: {=_FV(B33,"Preço")} -> 11.17 | E33: =D33 -> 11.17 | F33: 12.71 | G33: =IFERROR((D33-F33)/F33,"") -> -0.12116444 | H33: 0 | I33: =H33*F33 -> 0 | J33: =IFERROR(H33*D33,"") -> 0 | K33: =IFERROR(J33-I33,"") -> 0
A34: 46132 | B34: #VALUE! | C34: {=_FV(B34,"Variação")} -> 0.58 | D34: {=_FV(B34,"Preço")} -> 26.12 | E34: =D34 -> 26.12 | F34: 27.4 | G34: =IFERROR((D34-F34)/F34,"") -> -0.046715328 | H34: 5 | I34: =H34*F34 -> 137 | J34: =IFERROR(H34*D34,"") -> 130.6 | K34: =IFERROR(J34-I34,"") -> -6.4
A35: 46132 | B35: #VALUE! | C35: {=_FV(B35,"Variação")} -> 0.72 | D35: {=_FV(B35,"Preço")} -> 30.04 | E35: =D35 -> 30.04 | F35: 34.6 | G35: =IFERROR((D35-F35)/F35,"") -> -0.13179191 | H35: 5 | I35: =H35*F35 -> 173 | J35: =IFERROR(H35*D35,"") -> 150.2 | K35: =IFERROR(J35-I35,"") -> -22.8
A36: 46132 | B36: #VALUE! | C36: {=_FV(B36,"Variação")} -> 0.21 | D36: {=_FV(B36,"Preço")} -> 12.97 | E36: =D36 -> 12.97 | F36: 14.85 | G36: =IFERROR((D36-F36)/F36,"") -> -0.12659933 | H36: 10 | I36: =H36*F36 -> 148.5 | J36: =IFERROR(H36*D36,"") -> 129.7 | K36: =IFERROR(J36-I36,"") -> -18.8
B37: =SUBTOTAL(103,B31:B36) -> 6 | D37: =SUM(D31:D36) -> 127.68 | E37: =SUM(E31:E36) -> 127.68 | G37: =IFERROR(SUBTOTAL(109,G31:G36),"") -> -0.49468481 | I37: =SUM(I31:I36) -> 896.5 | J37: =SUM(J31:J36) -> 843.1 | K37: =IFERROR(SUM(K31:K36),"") -> -53.4

Sheet DIVIDENDOS
A1: 📅 CALENDÁRIO DE DIVIDENDOS - CARTEIRA RENATO
A3: HOJE: | B3: =TODAY() -> 46142 | D3: ALERTAS: | E3: Iminente (≤7d): | F3: =COUNTIFS(I6:I27,">=0",I6:I27,"<=7") -> 0 | G3: Em breve (8-15d): | H3: =COUNTIFS(I6:I27,">=8",I6:I27,"<=15") -> 2 | I3: Próximos 30d: | J3: =COUNTIFS(I6:I27,">=0",I6:I27,"<=30") -> 3
A5: TICKER | B5: TIPO | C5: DATA COM | D5: DATA PAGTO | E5: VALOR/AÇÃO | F5: MOEDA | G5: Nº AÇÕES | H5: VALOR TOTAL | I5: DIAS P/ PAGTO | J5: STATUS | K5: OBSERVAÇÕES
A6: PETR4 | B6: JCP | C6: 22/04/2026 | D6: 20/05/2026 | E6: 0.31311454 | F6: BRL | G6: 10 | H6: =E6*G6 -> 3.1311454 | I6: =D6-$B$3 -> 20 | J6: =IF(I6<0,"Pago",IF(I6<=7,"🔴 Iminente",IF(I6<=15,"🟡 Em breve",IF(I6<=30,"🟢 Próximo","Aguardando")))) -> 🟢 Próximo | K6: 1ª parcela JCP - data-com 22/04/2026
A7: PETR4 | B7: JCP | C7: 22/04/2026 | D7: 22/06/2026 | E7: 0.31311454 | F7: BRL | G7: 10 | H7: =E7*G7 -> 3.1311454 | I7: =D7-$B$3 -> 53 | J7: =IF(I7<0,"Pago",IF(I7<=7,"🔴 Iminente",IF(I7<=15,"🟡 Em breve",IF(I7<=30,"🟢 Próximo","Aguardando")))) -> Aguardando | K7: 2ª parcela JCP
A8: VALE3 | B8: Div+JCP | D8: Ago/2026 (esperado) | F8: BRL | G8: 10 | J8: Aguardando | K8: Semestral - último pago 04/03/2026. Próx esperado ago/2026
A9: BBAS3 | B9: JCP | C9: 13/05/2026 (est) | D9: 46332 | E9: 0.07 | F9: BRL | G9: 26 | H9: =E9*G9 -> 1.82 | I9: =D9-$B$3 -> 190 | J9: =IF(I9<0,"Pago",IF(I9<=7,"🔴 Iminente",IF(I9<=15,"🟡 Em breve",IF(I9<=30,"🟢 Próximo","Aguardando")))) -> Aguardando | K9: 2T26 (valor estimado)
A10: BBAS3 | B10: JCP | C10: 13/08/2026 (est) | D10: 46335 | E10: 0.07 | F10: BRL | G10: 26 | H10: =E10*G10 -> 1.82 | I10: =D10-$B$3 -> 193 | J10: =IF(I10<0,"Pago",IF(I10<=7,"🔴 Iminente",IF(I10<=15,"🟡 Em breve",IF(I10<=30,"🟢 Próximo","Aguardando")))) -> Aguardando | K10: 3T26 (valor estimado)
A11: BBAS3 | B11: JCP | C11: 46327 | D11: 46124 | E11: 0.07 | F11: BRL | G11: 26 | H11: =E11*G11 -> 1.82 | I11: =D11-$B$3 -> -18 | J11: =IF(I11<0,"Pago",IF(I11<=7,"🔴 Iminente",IF(I11<=15,"🟡 Em breve",IF(I11<=30,"🟢 Próximo","Aguardando")))) -> Pago | K11: Proventos complementares
A12: BBAS3 | B12: JCP | C12: 46327 | D12: 46307 | E12: 0.07 | F12: BRL | G12: 26 | H12: =E12*G12 -> 1.82 | I12: =D12-$B$3 -> 165 | J12: =IF(I12<0,"Pago",IF(I12<=7,"🔴 Iminente",IF(I12<=15,"🟡 Em breve",IF(I12<=30,"🟢 Próximo","Aguardando")))) -> Aguardando | K12: 4T26
A13: ABEV3 | B13: JCP | C13: 18/12/2025 | D13: 31/12/2026 | E13: 0.269 | F13: BRL | G13: 19 | H13: =E13*G13 -> 5.111 | I13: =D13-$B$3 -> 245 | J13: =IF(I13<0,"Pago",IF(I13<=7,"🔴 Iminente",IF(I13<=15,"🟡 Em breve",IF(I13<=30,"🟢 Próximo","Aguardando")))) -> Aguardando | K13: JCP bruto - data exata até 31/12/2026
A14: CPTS11 | B14: Rend. FII | C14: 30/04/2026 (est) | D14: 15/05/2026 | E14: 0.09 | F14: BRL | G14: 44 | H14: =E14*G14 -> 3.96 | I14: =D14-$B$3 -> 15 | J14: =IF(I14<0,"Pago",IF(I14<=7,"🔴 Iminente",IF(I14<=15,"🟡 Em breve",IF(I14<=30,"🟢 Próximo","Aguardando")))) -> 🟡 Em breve | K14: FII - distribuição MENSAL ~dia 15
A15: CPTS11 | B15: Rend. FII | C15: 29/05/2026 (est) | D15: 15/06/2026 | E15: 0.09 | F15: BRL | G15: 44 | H15: =E15*G15 -> 3.96 | I15: =D15-$B$3 -> 46 | J15: =IF(I15<0,"Pago",IF(I15<=7,"🔴 Iminente",IF(I15<=15,"🟡 Em breve",IF(I15<=30,"🟢 Próximo","Aguardando")))) -> Aguardando | K15: Rendimento mensal recorrente
A16: CURY3 | B16: Dividendo | C16: 46114 | D16: 31/12/2026 | E16: 0.4544752 | F16: BRL | G16: 5 | H16: =E16*G16 -> 2.272376 | I16: =D16-$B$3 -> 245 | J16: =IF(I16<0,"Pago",IF(I16<=7,"🔴 Iminente",IF(I16<=15,"🟡 Em breve",IF(I16<=30,"🟢 Próximo","Aguardando")))) -> Aguardando | K16: Parcela única - data exata ainda a divulgar
A17: DIRR3 | B17: Dividendo | C17: Jun/2026 (est) | D17: Jul/2026 (est) | E17: 1.78 | F17: BRL | G17: 10 | H17: =E17*G17 -> 17.8 | I17: ~75 dias | J17: Aguardando | K17: Semestral - histórico: jul e dez (valores estimados)
A18: AZZA3 | B18: Dividendo | C18: Dez/2026 (est) | D18: Dez/2026 (est) | E18: 1.58 | F18: BRL | G18: 20 | H18: =E18*G18 -> 31.6 | I18: ~8 meses | J18: Aguardando | K18: Anual fim de ano (base histórica último pago 30/12/2025)
A19: VIVA3 | B19: Dividendo | C19: Dez/2026 (est) | D19: Dez/2026 (est) | E19: 0.7 | F19: BRL | G19: 10 | H19: =E19*G19 -> 7 | I19: ~8 meses | J19: Aguardando | K19: Anual fim de ano (último pago 30/12/2025)
A20: SIMH3 | B20: JCP | C20: Mai/2026 (est) | D20: Mai/2026 (est) | E20: 0.14 | F20: BRL | G20: 1 | H20: =E20*G20 -> 0.14 | I20: ~30 dias | J20: 🟢 Próximo | K20: Último pagamento foi R$0,14 em 19/05/2025
A21: BMOB3 | B21: Div+JCP | C21: Dez/2026 (est) | D21: Dez/2026 (est) | E21: 1.59 | F21: BRL | G21: 5 | H21: =E21*G21 -> 7.95 | I21: ~8 meses | J21: Aguardando | K21: Anual - empresa sinalizou payout 100% lucro em 2026
A22: O | B22: Dividend | C22: 30/04/2026 | D22: 15/05/2026 | E22: 0.2705 | F22: USD | G22: ='CARTEIRA RENATO'!H14 -> 20.22817 | H22: =E22*G22 -> 5.47172 | I22: =DATEVALUE(D22)-$B$3 -> 15 | J22: =IF(I22<0,"Pago",IF(I22<=7,"🔴 Iminente",IF(I22<=15,"🟡 Em breve",IF(I22<=30,"🟢 Próximo","Aguardando")))) -> 🟡 Em breve | K22: Realty Income - MENSAL. Próximo de ~16 pagamentos/ano
A23: TSM | B23: Dividend | C23: =DATE(2026,6,11) -> 46184 | D23: =DATE(2026,7,9) -> 46212 | E23: 0.95 | F23: USD | G23: ='CARTEIRA RENATO'!H20 -> 1 | H23: =E23*G23 -> 0.95 | I23: =D23-$B$3 -> 70 | J23: =IF(I23<0,"Pago",IF(I23<=7,"🔴 Iminente",IF(I23<=15,"🟡 Em breve",IF(I23<=30,"🟢 Próximo","Aguardando")))) -> Aguardando | K23: Trimestral - 4T25 aprovado NT$6/ação (~US$0,95/ADR)
A24: BABA | B24: Dividend | C24: =DATE(2026,6,12) -> 46185 | D24: =DATE(2026,7,10) -> 46213 | E24: 1.05 | F24: USD | G24: ='CARTEIRA RENATO'!H21 -> 1 | H24: =E24*G24 -> 1.05 | I24: =D24-$B$3 -> 71 | J24: =IF(I24<0,"Pago",IF(I24<=7,"🔴 Iminente",IF(I24<=15,"🟡 Em breve",IF(I24<=30,"🟢 Próximo","Aguardando")))) -> Aguardando | K24: Anual - previsão com base no histórico (último US$0,95 em jul/2025)
A25: TCEHY | B25: Dividend | C25: 19/05/2026 | D25: 16/06/2026 | E25: 0.57 | F25: USD | G25: ='CARTEIRA RENATO'!H22 -> 1 | H25: =E25*G25 -> 0.57 | I25: =DATEVALUE(D25)-$B$3 -> 47 | J25: =IF(I25<0,"Pago",IF(I25<=7,"🔴 Iminente",IF(I25<=15,"🟡 Em breve",IF(I25<=30,"🟢 Próximo","Aguardando")))) -> Aguardando | K25: Anual - previsão com base no histórico (jun/ano anterior)
A26: PDD | B26: N/A | C26: - | D26: NÃO PAGA | E26: 0 | F26: USD | G26: ='CARTEIRA RENATO'!H23 -> 1 | H26: 0 | I26: N/A | J26: Não paga dividendos | K26: Empresa de crescimento - reinveste lucros
A27: SONY | B27: Dividend | C27: =DATE(2026,3,31) -> 46112 | D27: =DATE(2026,6,9) -> 46182 | E27: 0.07 | F27: USD | G27: ='CARTEIRA RENATO'!H24 -> 1 | H27: =E27*G27 -> 0.07 | I27: =D27-$B$3 -> 40 | J27: =IF(I27<0,"Pago",IF(I27<=7,"🔴 Iminente",IF(I27<=15,"🟡 Em breve",IF(I27<=30,"🟢 Próximo","Aguardando")))) -> Aguardando | K27: Semi-anual - data ex já passou (31/03), pagto garantido em jun
A29: TOTAIS (em BRL)
A30: Total em BRL (BR): | B30: =SUMIFS(H6:H21,F6:F21,"BRL",I6:I21,">=0") -> 27.025667
A31: Total em USD (Int'l): | B31: =SUMIFS(H22:H27,F22:F27,"USD",I22:I27,">=0") -> 8.11172
A32: Total USD convertido (BRL): | B32: =B31*CAMBIO!$C$2 -> 40.185461
A33: TOTAL GERAL A RECEBER (BRL): | B33: =B30+B32 -> 67.211128
A35: PRÓXIMOS 30 DIAS (ordenado por data)
A36: Ticker | B36: Tipo | C36: Data Com | D36: Data Pagto | E36: Valor/Ação
A37: {=IFERROR(_xlfn._xlws.SORT(_xlfn._xlws.FILTER(A6:E27,(I6:I27>=0)*(I6:I27<=30)),3,1),"Nenhum nos próximos 30 dias")} -> PETR4 | B37: JCP | C37: 22/04/2026 | D37: 20/05/2026 | E37: 0.31311454
A38: O | B38: Dividend | C38: 30/04/2026 | D38: 15/05/2026 | E38: 0.2705
A39: CPTS11 | B39: Rend. FII | C39: 30/04/2026 (est) | D39: 15/05/2026 | E39: 0.09
A40: VALE3 | B40: Div+JCP | C40: 0 | D40: Ago/2026 (esperado) | E40: 0
A51: DIRR3 | B51: Dividendo | C51: Jun/2026 (est) | D51: Jul/2026 (est) | E51: 1.78 | F51: BRL | G51: 10 | H51: =E51*G51 -> 17.8 | I51: ~75 dias | J51: Aguardando
A52: AZZA3 | B52: Dividendo | C52: Dez/2026 (est) | D52: Dez/2026 (est) | E52: 1.58 | F52: BRL | G52: 20 | H52: =E52*G52 -> 31.6 | I52: ~8 meses | J52: Aguardando
A53: VIVA3 | B53: Dividendo | C53: Dez/2026 (est) | D53: Dez/2026 (est) | E53: 0.7 | F53: BRL | G53: 10 | H53: =E53*G53 -> 7 | I53: ~8 meses | J53: Aguardando
A54: SIMH3 | B54: JCP | C54: Mai/2026 (est) | D54: Mai/2026 (est) | E54: 0.14 | F54: BRL | G54: 1 | H54: =E54*G54 -> 0.14 | I54: ~30 dias | J54: 🟢 Próximo
...

Sheet B3
A1: AÇÃO | B1: VAR. | C1: VALOR | D1: COMPRA | E1: RENT
A2: #VALUE! | B2: {=_FV(A2,"Variação (%)",TRUE)} -> 0.008 | C2: {=_FV(A2,"Preço")} -> 34.02 | D2: 36.38 | E2: =(C2-D2)/D2 -> -0.064870808
A3: #VALUE! | B3: {=_FV(A3,"Variação (%)",TRUE)} -> 0.025554 | C3: {=_FV(A3,"Preço")} -> 81.47 | D3: 79.53 | E3: =(C3-D3)/D3 -> 0.024393311
A4: #VALUE! | B4: {=_FV(A4,"Variação (%)",TRUE)} -> 0.000817 | C4: {=_FV(A4,"Preço")} -> 49 | D4: 46.36 | E4: =(C4-D4)/D4 -> 0.056945643
A5: #VALUE! | B5: {=_FV(A5,"Variação (%)",TRUE)} -> 0.018144 | C5: {=_FV(A5,"Preço")} -> 14.59 | D5: 13.22 | E5: =(C5-D5)/D5 -> 0.10363086
A6: #VALUE! | B6: {=_FV(A6,"Variação (%)",TRUE)} -> 0.024413 | C6: {=_FV(A6,"Preço")} -> 22.24 | E6: =(C6-D6)/D6 -> #DIV/0!
A7: #VALUE! | B7: {=_FV(A7,"Variação (%)",TRUE)} -> 0.033392 | C7: {=_FV(A7,"Preço")} -> 5.88 | E7: =(C7-D7)/D7 -> #DIV/0!
A8: #VALUE! | B8: {=_FV(A8,"Variação (%)",TRUE)} -> 0.068936 | C8: {=_FV(A8,"Preço")} -> 12.56 | E8: =(C8-D8)/D8 -> #DIV/0!
A9: #VALUE! | B9: {=_FV(A9,"Variação (%)",TRUE)} -> 0.007275 | C9: {=_FV(A9,"Preço")} -> 33.23 | E9: =(C9-D9)/D9 -> #DIV/0!
A10: #VALUE! | B10: {=_FV(A10,"Variação (%)",TRUE)} -> 0.016105 | C10: {=_FV(A10,"Preço")} -> 13.88 | E10: =(C10-D10)/D10 -> #DIV/0!
A11: #VALUE! | B11: {=_FV(A11,"Variação (%)",TRUE)} -> 0.016222 | C11: {=_FV(A11,"Preço")} -> 19.42 | E11: =(C11-D11)/D11 -> #DIV/0!
A12: #VALUE! | B12: {=_FV(A12,"Variação (%)",TRUE)} -> 0.016049 | C12: {=_FV(A12,"Preço")} -> 59.51 | E12: =(C12-D12)/D12 -> #DIV/0!
A13: #VALUE! | B13: {=_FV(A13,"Variação (%)",TRUE)} -> 0.005063 | C13: {=_FV(A13,"Preço")} -> 7.94 | E13: =(C13-D13)/D13 -> #DIV/0!

Sheet USD
A1: AÇÃO | B1: VAR. | C1: VALOR | D1: COMPRA | E1: RENT
A2: #VALUE! | B2: {=_FV(A2,"Variação (%)",TRUE)} -> -0.038757 | C2: {=_FV(A2,"Preço")} -> 201.14 | E2: =(C2-D2)/D2 -> #DIV/0!
A3: #VALUE! | B3: {=_FV(A3,"Variação (%)",TRUE)} -> 0.028755 | C3: {=_FV(A3,"Preço")} -> 383.52 | E3: =(C3-D3)/D3 -> #DIV/0!
A4: #VALUE! | B4: {=_FV(A4,"Variação (%)",TRUE)} -> -0.001858 | C4: {=_FV(A4,"Preço")} -> 214.94 | E4: =(C4-D4)/D4 -> #DIV/0!
A5: #VALUE! | B5: {=_FV(A5,"Variação (%)",TRUE)} -> 0.016431 | C5: {=_FV(A5,"Preço")} -> 64.055 | E5: =(C5-D5)/D5 -> #DIV/0!
B6: {=_FV(A6,"Variação (%)",TRUE)} -> #VALUE! | C6: {=_FV(A6,"Preço")} -> #VALUE! | E6: =(C6-D6)/D6 -> #VALUE!
B7: {=_FV(A7,"Variação (%)",TRUE)} -> #VALUE! | C7: {=_FV(A7,"Preço")} -> #VALUE! | E7: =(C7-D7)/D7 -> #VALUE!
B8: {=_FV(A8,"Variação (%)",TRUE)} -> #VALUE! | C8: {=_FV(A8,"Preço")} -> #VALUE! | E8: =(C8-D8)/D8 -> #VALUE!
B9: {=_FV(A9,"Variação (%)",TRUE)} -> #VALUE! | C9: {=_FV(A9,"Preço")} -> #VALUE! | E9: =(C9-D9)/D9 -> #VALUE!
B10: {=_FV(A10,"Variação (%)",TRUE)} -> #VALUE! | C10: {=_FV(A10,"Preço")} -> #VALUE! | E10: =(C10-D10)/D10 -> #VALUE!
B11: {=_FV(A11,"Variação (%)",TRUE)} -> #VALUE! | C11: {=_FV(A11,"Preço")} -> #VALUE! | E11: =(C11-D11)/D11 -> #VALUE!
B12: {=_FV(A12,"Variação (%)",TRUE)} -> #VALUE! | C12: {=_FV(A12,"Preço")} -> #VALUE! | E12: =(C12-D12)/D12 -> #VALUE!

Sheet CAMBIO
A1: MOEDA | B1: VAR. | C1: VALOR
A2: #VALUE! | B2: {=_FV(A2,"Variação (%)",TRUE)} -> -0.008407 | C2: {=_FV(A2,"Preço")} -> 4.954
A3: #VALUE! | B3: {=_FV(A3,"Variação (%)",TRUE)} -> -0.00312 | C3: {=_FV(A3,"Preço")} -> 5.8156
A4: #VALUE! | B4: {=_FV(A4,"Variação (%)",TRUE)} -> -0.006845 | C4: {=_FV(A4,"Preço")} -> 0.7255
A5: #VALUE! | B5: {=_FV(A5,"Variação (%)",TRUE)} -> 0.001619 | C5: {=_FV(A5,"Preço")} -> 6.742

Sheet RESUMO
A1: CARTEIRA | B1: Nº AÇÕES | C1: VAL. INVEST. | D1: VAL. ATUAL | E1: LUCRO/PERDA | F1: RENT. TOTAL
A2: AÇÕES BRASILEIRAS | B2: ='CARTEIRA RENATO'!B7 -> 5 | C2: =SUM('CARTEIRA RENATO'!I2:I6) -> 2671.82 | D2: =SUM('CARTEIRA RENATO'!J2:J6) -> 2509.51 | E2: =SUM('CARTEIRA RENATO'!K2:K6) -> -162.31 | F2: =IFERROR(E2/C2,"") -> -0.060748853
A3: AÇÕES EUA (REITS) | B3: ='CARTEIRA RENATO'!B15 -> 1 | C3: ='CARTEIRA RENATO'!I14 -> 1293.39 | D3: ='CARTEIRA RENATO'!J14*CAMBIO!C2 -> 6418.9742 | E3: ='CARTEIRA RENATO'!K14*CAMBIO!C2 -> 11.520177 | F3: =IFERROR('CARTEIRA RENATO'!K15/'CARTEIRA RENATO'!I14,"") -> 0.0017979336
A4: AÇÕES ASIÁTICAS | B4: ='CARTEIRA RENATO'!B27 -> 7 | C4: =SUM('CARTEIRA RENATO'!I20:I26) -> 836.3771 | D4: =SUM('CARTEIRA RENATO'!J20:J26)*CAMBIO!C2 -> 4218.7447 | E4: ='CARTEIRA RENATO'!K27*CAMBIO!C2 -> 75.332506 | F4: =IFERROR('CARTEIRA RENATO'!K27/SUM('CARTEIRA RENATO'!I20:I26),"") -> 0.018181273
A5: SMALL CAPS BR | B5: ='CARTEIRA RENATO'!B37 -> 6 | C5: ='CARTEIRA RENATO'!I37 -> 896.5 | D5: ='CARTEIRA RENATO'!J37 -> 843.1 | E5: ='CARTEIRA RENATO'!K37 -> -53.4 | F5: =IFERROR(E5/C5,"") -> -0.059564975
A6: TOTAL GERAL | B6: =SUM(B2:B5) -> 19 | C6: =C2+C5+(C3+C4)*CAMBIO!C2 -> 14119.186 | D6: =SUM(D2:D5) -> 13990.329 | E6: =SUM(E2:E5) -> -128.85732 | F6: =IF(C6=0,0,E6/C6) -> -0.0091263983
